Workbook

Sheet 25.Q2
A1: 报价总价比价 (Q2 招标)
A2: Consignor | B2: Consignee | C2: POL | D2: POD | E2: Payer | F2: Contact | G2: Transport | H2: Volume/Q2 | I2: Rolig | J2: Geodis | K2: 凯福 | L2: 合力通 | M2: 宝优 | N2: 舫心 | O2: Superchain | P2: 睿弘 | Q2: DSV | R2: 华洋 | S2: 青岛中外运
A3: AI-Turkey | Turkey (Izmit) | Q2 招标
A4: SAI - 3 Gaobao Lake East Rd, Yubei, Chongqing | B4: AI Termal Sistemleri A.Ş., Kocaeli/Izmit | C4: SHA | D4: Izmit | E4: AITURKEY | F4: Dilek Elmaser Polat | G4: D2D | H4: 15 | I4: 7680 | J4: 6633 | L4: 6385 | M4: 7200 | N4: 5450 | O4: 6300 | P4: / | Q4: 6822
A5: AIMX | Mexico (Manzanillo) | Q2 招标
A6: AITH (Thailand) | B6: AIMX Manzanillo Port | C6: Laem Chabang | D6: MANZANILLO | E6: AIMX | G6: CIF | H6: 3 | I6: 2788 | J6: 2860 | K6: 3430 | N6: 2480 | O6: 3550 | P6: /
A7: DELTA ELECTRONICS (Thailand) | B7: AIMX Manzanillo Port | C7: Bangkok | D7: MANZANILLO | E7: AIMX | G7: CIF | H7: 19 | I7: 2688 | J7: 2860 | K7: 3430 | N7: 2480 | O7: 3800 | P7: /
A8: AINT - 666 Wenchang Rd | B8: AIMX Manzanillo Port | C8: SHA | D8: MANZANILLO | E8: AIMX | G8: CIF | H8: 21 | I8: 2803 | J8: 2420 | K8: 2530 | L8: 4060 | M8: 4626 | N8: 2260 | O8: 3550 | P8: 2800 | Q8: 2266
A9: Creative Components, India | B9: AIMX Manzanillo Port | C9: Nhava Sheva | D9: MANZANILLO | E9: AIMX | G9: CIF | H9: 18 | I9: 3863 | J9: 3080 | K9: 4000 | N9: 3100 | O9: 5200 | P9: /
A10: Dalian ABIC | B10: AIMX Manzanillo Port | C10: Dalian | D10: MANZANILLO | E10: AIMX | G10: CIF | H10: 12 | I10: 2483 | J10: 2530 | K10: 2200 | M10: 5226 | N10: 2180 | O10: 3900 | P10: / | Q10: 1921
A11: AIUS | USA (HOU / Detroit / Savanna) | Q2 招标
A12: AINT - 666 Wenchang Rd | B12: GTZ Warehouse, McAllen, TX | C12: SHA | D12: HOU | E12: AIUS | G12: D2D | H12: 6 | I12: 7245 | J12: 8334 | K12: 6030 | L12: 6960 | M12: 8276 | N12: 6145 | O12: 7300 | P12: 5600 | Q12: 6365 | R12: 8945
A13: AISH - 108 Chunguang Rd | B13: FTZ Metro Warehouse, MI | C13: SHA | D13: Detroit | E13: AIUS | G13: D2D | H13: 6 | I13: 6205 | J13: 5947 | K13: 7180 | L13: 7041 | M13: 7650 | N13: 5495 | O13: 7150 | P13: 5100 | Q13: 6915 | R13: 9561
A14: AITH (Thailand) | B14: AIUS Baxter, Winchester, TN | C14: Laem Chabang | D14: Savanna | E14: AIUS | G14: D2D | H14: 10 | I14: 6780 | J14: 3720 | K14: 6080 | N14: 6065 | O14: 7750 | P14: /
A15: AINT - 666 Wenchang Rd | B15: AIUS Baxter, Winchester, TN | C15: SHA | D15: Savanna | E15: AIUS | G15: D2D | H15: 8 | I15: 7055 | J15: 4895 | K15: 6030 | L15: 7560 | M15: 8111 | N15: 6145 | O15: 7200 | P15: 5900 | Q15: 6465 | R15: 10261
A16: AISH | Asia → SHA (inbound) | Q2 招标
A17: DELTA ELECTRONICS (Thailand) | B17: AINT - 666 Wenchang Rd | C17: Laemchabang | D17: SHA | E17: AISH | F17: Kevin | G17: D2D | H17: 15 | I17: 1715 | J17: 2053 | K17: 1650 | N17: 1850 | O17: 1790 | P17: /
A18: Woory Industrial, Korea | B18: AINT - 666 Wenchang Rd | C18: Incheon | D18: SHA | E18: AISH | F18: Kevin | G18: D2D | H18: 7 | I18: 1859 | J18: 1818 | K18: 1950 | N18: 1800 | O18: 1690 | P18: /
A19: AINT - 666 Wenchang Rd | B19: AI Termal Sistemleri A.Ş., Kocaeli/Izmit | C19: SHA | D19: Izmit | E19: AISH | F19: Kevin | G19: D2D | H19: 45 | I19: 4950 | J19: 5735 | L19: 5420 | M19: 6226 | N19: 4440 | O19: 4900 | P19: / | Q19: 5915
A20: AITH | Thailand (Laemchabang) | Q2 招标
A21: AITH (Thailand) | B21: AISK, Nitra, Slovakia | C21: Laem Chabang | D21: Koper | E21: AITH | F21: Pornsuda | G21: D2D | H21: 4 | I21: 5135 | J21: 6218 | K21: 6360 | N21: 8280 | O21: 6550 | P21: /
A22: AISH - 108 Chunguang Rd | B22: AITH, Chonburi Thailand | C22: SHA | D22: Laemchabang | E22: AITH | F22: Pornsuda | G22: D2D | H22: 3 | I22: 1870 | J22: 2833 | K22: 2330 | M22: 2426 | N22: 2360 | O22: 2400 | P22: 3400 | Q22: 2190
A23: Shanghai Huafon Aluminium | B23: AITH, Rayong Thailand | C23: SHA | D23: Laemchabang | E23: AITH | F23: Pornsuda | G23: D2D | H23: 12 | I23: 1895 | J23: 2833 | K23: 2330 | M23: 2300 | N23: 2360 | O23: 2400 | P23: 3400 | Q23: 2190
A24: Hyo Seong Electric (Tianjin) | B24: AITH, Chonburi Thailand | C24: Tianjin | D24: Laemchabang | E24: AITH | F24: Pornsuda | G24: D2D | H24: 3 | I24: 1870 | J24: 2908 | K24: 2350 | M24: 2550 | N24: 3550 | O24: 2800 | P24: / | Q24: 2121
A25: OSE Industries, Dubai | B25: AITH, Rayong Thailand | C25: Dubai | D25: Laemchabang | E25: AITH | F25: Pornsuda | G25: D2D | H25: 3 | I25: 1360 | J25: 2250 | N25: 2225 | O25: 3900 | P25: /
A26: AISK | Slovakia (Hamburg) | Q2 招标
A27: AINT - 666 Wenchang Rd | B27: AISK, Nitra, Slovakia | C27: SHA | D27: Koper | E27: AISK | F27: Bafrnec, Marcel | G27: D2D | H27: 3 | I27: 5110 | J27: 6108 | M27: 6026 | N27: 5560 | O27: 5700 | P27: / | Q27: 5315
A28: Creative Components, India | B28: AISK, Nitra, Slovakia | C28: India | D28: Koper | E28: AISK | F28: Bafrnec, Marcel | G28: D2D | H28: 1 | I28: 5330 | J28: 4540 | N28: 5500 | O28: 5700 | P28: /
A30: 仅海运费比价 (Q2 招标)
A31: Consignor | B31: Consignee | C31: POL | D31: POD | E31: Payer | F31: Contact | G31: Transport | H31: Volume/Q2 | I31: Rolig | J31: Geodis | K31: 凯福 | L31: 合力通 | M31: 宝优 | N31: 舫心 | O31: Superchain | P31: 睿弘 | Q31: DSV | R31: 华洋 | S31: 青岛中外运
A32: AI-Turkey | Turkey (Izmit) | Q2 招标
A33: SAI - 3 Gaobao Lake East Rd, Yubei, Chongqing | B33: AI Termal Sistemleri A.Ş., Kocaeli/Izmit | C33: SHA | D33: Izmit | E33: AITURKEY | G33: D2D | H33: 15 | I33: 3200 | J33: 4950 | L33: 4475 | M33: 4150 | N33: 3700 | O33: 4550 | P33: / | Q33: 4200
A34: AIMX | Mexico (Manzanillo) | Q2 招标
A35: AITH (Thailand) | B35: AIMX Manzanillo Port | C35: Laem Chabang | D35: MANZANILLO | E35: AIMX | G35: CIF | H35: 3 | I35: 2000 | J35: 2860 | K35: 2750 | N35: 1800 | O35: 2465 | P35: /
A36: DELTA ELECTRONICS (Thailand) | B36: AIMX Manzanillo Port | C36: Bangkok | D36: MANZANILLO | E36: AIMX | G36: CIF | H36: 19 | I36: 1900 | J36: 2860 | K36: 2750 | N36: 1800 | O36: 2685 | P36: /
A37: AINT - 666 Wenchang Rd | B37: AIMX Manzanillo Port | C37: SHA | D37: MANZANILLO | E37: AIMX | G37: CIF | H37: 21 | I37: 1700 | J37: 2420 | K37: 1650 | L37: 3200 | M37: 2500 | N37: 1500 | O37: 2750 | P37: 1900 | Q37: 1300
A38: Creative Components, India | B38: AIMX Manzanillo Port | C38: Nhava Sheva | D38: MANZANILLO | E38: AIMX | G38: CIF | H38: 18 | I38: 2200 | J38: 3080 | K38: 2650 | N38: 2200 | O38: 3550 | P38: /
A39: Dalian ABIC | B39: AIMX Manzanillo Port | C39: Dalian | D39: MANZANILLO | E39: AIMX | G39: CIF | H39: 12 | I39: 1700 | J39: 2530 | K39: 1650 | M39: 3000 | N39: 1650 | O39: 3330 | P39: / | Q39: 1300
A40: AIUS | USA (HOU / Detroit / Savanna) | Q2 招标
A41: AINT - 666 Wenchang Rd | B41: GTZ Warehouse, McAllen, TX | C41: SHA | D41: HOU | E41: AIUS | G41: D2D | H41: 6 | I41: 3725 | J41: 4885 | K41: 2700 | L41: 3550 | M41: 4100 | N41: 2900 | O41: 4260 | P41: 2600 | Q41: 2700 | R41: 2900
...

Sheet 25.7-8月
A1: Lane | B1: Consignor | C1: Consignee | D1: POL | E1: POD | F1: Incoterm | G1: Q3 HQ40 Demand | H1: Booking | I1: Doc | J1: THC | K1: Loading | L1: Customs | M1: B/L | N1: Local Subtotal | O1: Dest Subtotal | P1: Sea Freight | Q1: Transit Time | R1: Total (USD) | S1: Winning Forwarder
A2: AI-Turkey | Turkey (Izmit) | 2 条航线 | Q3 季需求 50 HQ40
A3: SHA-Izmit | B3: AINT - 666 Wenchang Rd, Tongzhou, Nantong | C3: AI Termal Sistemleri A.Ş., Kocaeli/Izmit | D3: SHA | E3: Izmit | F3: DAP | G3: 35 | H3: 70 | I3: 70 | J3: 140 | K3: 400 | L3: 10 | M3: 70 | N3: =SUM(H3:M3) -> 760 | O3: 950 | P3: 3480 | Q3: — | R3: =IFERROR(N3+IF(ISNUMBER(O3),O3,0)+IF(ISNUMBER(P3),P3,0),"") -> 5190 | S3: Bestunit
A4: SAI-Izmit | B4: SAI - 3 Gaobao Lake East Rd, Yubei, Chongqing | C4: AI Termal Sistemleri A.Ş., Kocaeli/Izmit | D4: SHA | E4: Izmit | F4: EXW | G4: 15 | H4: 70 | I4: 70 | J4: 140 | K4: 200 | L4: 20 | M4: 50 | N4: =SUM(H4:M4) -> 550 | O4: 950 | P4: 3480 | Q4: — | R4: =IFERROR(N4+IF(ISNUMBER(O4),O4,0)+IF(ISNUMBER(P4),P4,0),"") -> 4980 | S4: Bestunit
A5: AIMX | Mexico (Manzanillo) | 12 条航线 | Q3 季需求 69 HQ40
A6: Laem-Manzanillo | B6: AITH (Thailand) | C6: AIMX Manzanillo Port | D6: Laem Chabang | E6: MANZANILLO | F6: CIF | G6: 8 | H6: 70 | I6: 50 | J6: 260 | K6: 250 | L6: 90 | M6: 80 | N6: =SUM(H6:M6) -> 800 | O6: N/A | P6: 3500 | Q6: — | R6: =IFERROR(N6+IF(ISNUMBER(O6),O6,0)+IF(ISNUMBER(P6),P6,0),"") -> 4300 | S6: Kaifu
A7: Bangkok-Manzanillo | B7: DELTA ELECTRONICS (Thailand) | C7: AIMX Manzanillo Port | D7: Bangkok | E7: MANZANILLO | F7: CIF | G7: 15 | H7: 70 | I7: 50 | J7: 260 | K7: 325 | L7: 90 | M7: 80 | N7: =SUM(H7:M7) -> 875 | O7: N/A | P7: 3500 | Q7: — | R7: =IFERROR(N7+IF(ISNUMBER(O7),O7,0)+IF(ISNUMBER(P7),P7,0),"") -> 4375 | S7: Kaifu
A8: Nhava-Manzanillo | B8: Creative Component, Pune, India | C8: AIMX Manzanillo Port | D8: Nhava Sheva | E8: MANZANILLO | F8: CIF | G8: 8 | H8: 70 | I8: 80 | J8: 160 | K8: 1000 | L8: 50 | M8: 75 | N8: =SUM(H8:M8) -> 1435 | O8: N/A | P8: 2500 | Q8: — | R8: =IFERROR(N8+IF(ISNUMBER(O8),O8,0)+IF(ISNUMBER(P8),P8,0),"") -> 3935 | S8: Kaifu
A9: Dalian-Manzanillo | B9: Dalian Aibike Air Conditioning Parts | C9: AIMX Manzanillo Port | D9: Dalian | E9: MANZANILLO | F9: CIF | G9: 4 | H9: 70 | I9: 70 | J9: 145 | K9: 200 | L9: 15 | M9: 50 | N9: =SUM(H9:M9) -> 550 | O9: N/A | P9: 3000 | Q9: — | R9: =IFERROR(N9+IF(ISNUMBER(O9),O9,0)+IF(ISNUMBER(P9),P9,0),"") -> 3550 | S9: Superchain
A10: Incheon-Manzanillo | B10: Woory Industrial, Korea | C10: AIMX Manzanillo Port | D10: Incheon | E10: MANZANILLO | F10: CIF | G10: 8 | H10: 70 | I10: 35 | J10: 145 | K10: 350 | L10: 150 | M10: 50 | N10: =SUM(H10:M10) -> 800 | O10: N/A | P10: 2700 | Q10: — | R10: =IFERROR(N10+IF(ISNUMBER(O10),O10,0)+IF(ISNUMBER(P10),P10,0),"") -> 3500 | S10: Superchain
A11: SHA-Manzanillo (Bokang) | B11: Bokang (FOB Shanghai) | C11: AIMX Manzanillo Port | D11: SHA | E11: MANZANILLO | F11: CIF | G11: 3 | H11: 70 | I11: 70 | J11: 145 | K11: 50 | L11: 15 | M11: 60 | N11: =SUM(H11:M11) -> 410 | O11: N/A | P11: 2700 | Q11: — | R11: =IFERROR(N11+IF(ISNUMBER(O11),O11,0)+IF(ISNUMBER(P11),P11,0),"") -> 3110 | S11: Superchain
A12: SHA-Manzanillo (Ganglong) | B12: Ganglong (EXW Shanghai) | C12: AIMX Manzanillo Port | D12: SHA | E12: MANZANILLO | F12: CIF | G12: 3 | H12: 70 | I12: 70 | J12: 145 | K12: 230 | L12: 15 | M12: 60 | N12: =SUM(H12:M12) -> 590 | O12: N/A | P12: 2700 | Q12: — | R12: =IFERROR(N12+IF(ISNUMBER(O12),O12,0)+IF(ISNUMBER(P12),P12,0),"") -> 3290 | S12: Superchain
A13: SHA-Manzanillo (PMC) | B13: PMC (EXW Nanjing) | C13: AIMX Manzanillo Port | D13: SHA | E13: MANZANILLO | F13: CIF | G13: 3 | H13: 70 | I13: 70 | J13: 145 | K13: 550 | L13: 15 | M13: 60 | N13: =SUM(H13:M13) -> 910 | O13: N/A | P13: 2700 | Q13: — | R13: =IFERROR(N13+IF(ISNUMBER(O13),O13,0)+IF(ISNUMBER(P13),P13,0),"") -> 3610 | S13: Superchain
A14: SHA-Manzanillo (Boling) | B14: Chongqing Boling (EXW Chongqing) | C14: AIMX Manzanillo Port | D14: SHA | E14: MANZANILLO | F14: CIF | G14: 3 | H14: 70 | I14: 70 | J14: 145 | K14: 1550 | L14: 15 | M14: 60 | N14: =SUM(H14:M14) -> 1910 | O14: N/A | P14: 2700 | Q14: — | R14: =IFERROR(N14+IF(ISNUMBER(O14),O14,0)+IF(ISNUMBER(P14),P14,0),"") -> 4610 | S14: Superchain
A15: SHA-Manzanillo (Huafeng) | B15: Huafeng (EXW Shanghai) | C15: AIMX Manzanillo Port | D15: SHA | E15: MANZANILLO | F15: CIF | G15: 3 | H15: 70 | I15: 70 | J15: 145 | K15: 250 | L15: 15 | M15: 60 | N15: =SUM(H15:M15) -> 610 | O15: N/A | P15: 2700 | Q15: — | R15: =IFERROR(N15+IF(ISNUMBER(O15),O15,0)+IF(ISNUMBER(P15),P15,0),"") -> 3310 | S15: Superchain
A16: SHA-Manzanillo (Xinrui) | B16: Xinrui (EXW Shaoxing) | C16: AIMX Manzanillo Port | D16: SHA | E16: MANZANILLO | F16: CIF | G16: 3 | H16: 70 | I16: 70 | J16: 145 | K16: 500 | L16: 15 | M16: 60 | N16: =SUM(H16:M16) -> 860 | O16: N/A | P16: 2700 | Q16: — | R16: =IFERROR(N16+IF(ISNUMBER(O16),O16,0)+IF(ISNUMBER(P16),P16,0),"") -> 3560 | S16: Superchain
A17: SHA-Manzanillo (AITD) | B17: AITD (EXW Nantong) | C17: AIMX Manzanillo Port | D17: SHA | E17: MANZANILLO | F17: CIF | G17: 8 | H17: 70 | I17: 70 | J17: 145 | K17: 350 | L17: 15 | M17: 60 | O17: N/A | P17: 2700 | Q17: — | S17: Superchain
A18: AIUS | USA (HOU / Detroit / Savanna) | 5 条航线 | Q3 季需求 31 HQ40
A19: SHA-HOU | B19: AINT - 666 Wenchang Rd, Tongzhou, Nantong | C19: GTZ Warehouse, McAllen, TX | D19: SHA | E19: HOU | F19: DAP | G19: 6 | H19: 70 | I19: 70 | J19: 140 | K19: 400 | L19: 10 | M19: 70 | N19: =SUM(H19:M19) -> 760 | O19: 2685 | P19: 4600 | Q19: — | R19: =IFERROR(N19+IF(ISNUMBER(O19),O19,0)+IF(ISNUMBER(P19),P19,0),"") -> 8045 | S19: Bestunit
A20: SHA-Detroit | B20: AISH - 108 Chunguang Rd, Minhang, Shanghai | C20: FTZ Metro Warehouse, Highland Park, MI | D20: SHA | E20: Detroit | F20: DAP | G20: 6 | H20: 70 | I20: 70 | J20: 140 | K20: 250 | L20: 10 | M20: 70 | N20: =SUM(H20:M20) -> 610 | O20: 885 | P20: 5000 | Q20: — | R20: =IFERROR(N20+IF(ISNUMBER(O20),O20,0)+IF(ISNUMBER(P20),P20,0),"") -> 6495 | S20: Bestunit
A21: Laem-Savanna | B21: AITH (Thailand) | C21: AIUS Baxter, Winchester, TN | D21: Laem Chabang | E21: Savanna | F21: DAP | G21: 1 | H21: 70 | I21: 70 | J21: 140 | K21: 300 | L21: 30 | M21: 70 | N21: =SUM(H21:M21) -> 680 | O21: 2785 | P21: 6182 | Q21: — | R21: =IFERROR(N21+IF(ISNUMBER(O21),O21,0)+IF(ISNUMBER(P21),P21,0),"") -> 9647 | S21: Bestunit
A22: Nhava-Savanna | B22: Divine & Creative, India | C22: AIUS Baxter, Winchester, TN | D22: Nhava Sheva | E22: Savanna | F22: DAP | G22: 10 | H22: 70 | I22: 80 | J22: 160 | K22: 1000 | L22: 50 | M22: 75 | N22: =SUM(H22:M22) -> 1435 | O22: 2785 | P22: 4870 | Q22: — | R22: =IFERROR(N22+IF(ISNUMBER(O22),O22,0)+IF(ISNUMBER(P22),P22,0),"") -> 9090 | S22: Bestunit
A23: SHA-Savanna | B23: AINT - 666 Wenchang Rd, Tongzhou, Nantong | C23: AIUS Baxter, Winchester, TN | D23: SHA | E23: Savanna | F23: DAP | G23: 8 | H23: 70 | I23: 70 | J23: 140 | K23: 400 | L23: 10 | M23: 70 | O23: 2785 | P23: 4932 | Q23: — | S23: Bestunit
A24: AISH | Asia → SHA (inbound) | 2 条航线 | Q3 季需求 22 HQ40
A25: Laem-SHA | B25: DELTA ELECTRONICS (Thailand) | C25: AINT - 666 Wenchang Rd, Tongzhou, Nantong | D25: Laem Chabang | E25: SHA | F25: DAP | G25: 15 | H25: 70 | I25: 50 | J25: 260 | K25: 325 | L25: 90 | M25: 80 | N25: =SUM(H25:M25) -> 875 | O25: 600 | P25: 30 | Q25: — | R25: =IFERROR(N25+IF(ISNUMBER(O25),O25,0)+IF(ISNUMBER(P25),P25,0),"") -> 1505 | S25: Superchain
A26: Incheon-SHA | B26: Woory Industrial, Korea | C26: AINT - 666 Wenchang Rd, Tongzhou, Nantong | D26: Incheon | E26: SHA | F26: DAP | G26: 7 | H26: 70 | I26: 35 | J26: 145 | K26: 350 | L26: 150 | M26: 50 | O26: 600 | P26: 1 | Q26: — | S26: Superchain
A27: AITH | Thailand (Laemchabang) | 4 条航线 | Q3 季需求 21 HQ40
A28: SHA-Laem | B28: AISH - 108 Chunguang Rd, Minhang, Shanghai | C28: AITH, Chonburi 20230 Thailand | D28: SHA | E28: Laemchabang | F28: DAP | G28: 3 | H28: 70 | I28: 70 | J28: 140 | K28: 250 | L28: 10 | M28: 70 | N28: =SUM(H28:M28) -> 610 | O28: 800 | P28: 440 | Q28: — | R28: =IFERROR(N28+IF(ISNUMBER(O28),O28,0)+IF(ISNUMBER(P28),P28,0),"") -> 1850 | S28: Geodis (泰本地 $1725)
A29: SHA-Laem (Huafon) | B29: Shanghai Huafon Aluminium Corp. | C29: AITH, Rayong 21140 Thailand | D29: SHA | E29: Laemchabang | F29: DAP | G29: 12 | H29: 70 | I29: 70 | J29: 140 | K29: 250 | L29: 10 | M29: 70 | N29: =SUM(H29:M29) -> 610 | O29: 800 | P29: 440 | Q29: — | R29: =IFERROR(N29+IF(ISNUMBER(O29),O29,0)+IF(ISNUMBER(P29),P29,0),"") -> 1850 | S29: Geodis (泰本地 $1717)
A30: Tianjin-Laem | B30: Hyo Seong Electric (Tianjin) | C30: AITH, Chonburi 20230 Thailand | D30: Tianjin | E30: Laemchabang | F30: DAP | G30: 3 | H30: 70 | I30: 70 | J30: 140 | K30: 420 | L30: 30 | M30: 70 | N30: =SUM(H30:M30) -> 800 | O30: 800 | P30: 440 | Q30: — | R30: =IFERROR(N30+IF(ISNUMBER(O30),O30,0)+IF(ISNUMBER(P30),P30,0),"") -> 2040 | S30: Geodis (泰本地 $2062)
A31: Dubai-Laem | B31: OSE Industries LLC, Dubai | C31: AITH, Rayong 21140 Thailand | D31: Dubai | E31: Laemchabang | F31: DAP | G31: 3 | H31: 70 | I31: 70 | J31: 140 | K31: 420 | L31: 30 | M31: 70 | N31: =SUM(H31:M31) -> 800 | O31: 800 | P31: 150 | Q31: — | R31: =IFERROR(N31+IF(ISNUMBER(O31),O31,0)+IF(ISNUMBER(P31),P31,0),"") -> 1750 | S31: Geodis (泰本地 $1956)
A32: AITH-AISK (泰国本地) | B32: AITH | C32: AISK | D32: AITH | E32: AISK | F32: DAP | Q32: — | S32: Cargo (泰本地 $6000)
A33: AISK | Slovakia (Hamburg) | 3 条航线 | Q3 季需求 15 HQ40
A34: SHA-Koper | B34: AINT - 666 Wenchang Rd, Tongzhou, Nantong | C34: AISK, Nitra, Slovakia | D34: SHA | E34: Koper | F34: DAP | G34: 3 | H34: 70 | I34: 70 | J34: 140 | K34: 400 | L34: 10 | M34: 70 | N34: =SUM(H34:M34) -> 760 | O34: 2200 | P34: 2680 | Q34: — | R34: =IFERROR(N34+IF(ISNUMBER(O34),O34,0)+IF(ISNUMBER(P34),P34,0),"") -> 5640 | S34: Rohlig
A35: Nhava-Hamburg | B35: Divine Tooling | C35: AISK, Nitra, Slovakia | D35: Nhava Sheva | E35: Hamburg | F35: DAP | G35: 10 | H35: 70 | I35: 70 | J35: 140 | K35: 300 | L35: 250 | M35: 70 | N35: =SUM(H35:M35) -> 900 | O35: 2200 | P35: 1995 | Q35: — | R35: =IFERROR(N35+IF(ISNUMBER(O35),O35,0)+IF(ISNUMBER(P35),P35,0),"") -> 5095 | S35: Rohlig
A36: Nhava-Koper | B36: Delta Electronics | C36: AISK, Nitra, Slovakia | D36: Nhava Sheva | E36: Koper | F36: DAP | G36: 2 | H36: 70 | I36: 70 | J36: 140 | K36: 300 | L36: 30 | M36: 70 | N36: =SUM(H36:M36) -> 680 | O36: 2200 | P36: 2785 | Q36: — | R36: =IFERROR(N36+IF(ISNUMBER(O36),O36,0)+IF(ISNUMBER(P36),P36,0),"") -> 5665 | S36: Rohlig

Sheet 25.9月
A1: Lane | B1: Consignor | C1: Consignee | D1: POL | E1: POD | F1: Incoterm | G1: HQ40 Demand | H1: Booking | I1: Doc | J1: THC | K1: Loading | L1: Customs | M1: B/L | N1: Local Subtotal | O1: Dest Subtotal | P1: Sea Freight | Q1: Transit Time | R1: Total (USD) | S1: Winning Forwarder
A2: AI-Turkey | Turkey (Izmit) | 2 条航线 | 月需求 26 HQ40
A3: SHA-Izmit | B3: AINT - 666 Wenchang Rd, Tongzhou, Nantong | C3: AI Termal Sistemleri A.Ş., İstanbul | D3: SHA | E3: Izmit | F3: DAP | G3: 22 | H3: 70 | I3: 70 | J3: 140 | K3: 400 | L3: 10 | M3: 70 | N3: =SUM(H3:M3) -> 760 | O3: 950 | P3: 2800 | Q3: 8-10 wks | R3: =IFERROR(N3+IF(ISNUMBER(O3),O3,0)+IF(ISNUMBER(P3),P3,0),"") -> 4510 | S3: 合力通
A4: SAI-Izmit | B4: SAI - 3 Gaobao Lake East Rd, Yubei, Chongqing | C4: AI Termal Sistemleri A.Ş., İstanbul | D4: SHA | E4: Izmit | F4: EXW | G4: 4 | H4: 70 | I4: 70 | J4: 140 | K4: 200 | L4: 20 | M4: 50 | N4: =SUM(H4:M4) -> 550 | O4: 950 | P4: 4294 | Q4: — | R4: =IFERROR(N4+IF(ISNUMBER(O4),O4,0)+IF(ISNUMBER(P4),P4,0),"") -> 5794 | S4: Freetrans
A5: AIMX | Mexico (Manzanillo) | 15 条航线 | 月需求 35 HQ40
A6: Laem-Manzanillo | B6: AITH | C6: Puebla + Saltillo | D6: Laemchabang | E6: MANZANILLO | F6: CIF | G6: 11 | H6: 70 | I6: 50 | J6: 260 | K6: 250 | L6: 90 | M6: 80 | N6: =SUM(H6:M6) -> 800 | O6: N/A | P6: 3050 | Q6: — | R6: =IFERROR(N6+IF(ISNUMBER(O6),O6,0)+IF(ISNUMBER(P6),P6,0),"") -> 3850 | S6: Freetrans
A7: Bangkok-Manzanillo | B7: DELTA | C7: Saltillo | D7: Bangkok | E7: MANZANILLO | F7: CIF | G7: 3 | H7: 70 | I7: 50 | J7: 260 | K7: 325 | L7: 90 | M7: 80 | N7: =SUM(H7:M7) -> 875 | O7: N/A | P7: 2995 | Q7: — | R7: =IFERROR(N7+IF(ISNUMBER(O7),O7,0)+IF(ISNUMBER(P7),P7,0),"") -> 3870 | S7: Freetrans
A8: Laem-Manzanillo (TNC) | B8: TNC | C8: Puebla | D8: Laemchabang | E8: MANZANILLO | F8: CIF | G8: 0.5 | H8: 70 | I8: 50 | J8: 260 | K8: 250 | L8: 90 | M8: 80 | N8: =SUM(H8:M8) -> 800 | O8: N/A | P8: 3200 | Q8: — | R8: =IFERROR(N8+IF(ISNUMBER(O8),O8,0)+IF(ISNUMBER(P8),P8,0),"") -> 4000 | S8: Freetrans/Kaifu
A9: Nhava-Manzanillo | B9: Creative Components | C9: Saltillo | D9: Nhava Sheva | E9: MANZANILLO | F9: CIF | G9: 2 | H9: 70 | I9: 80 | J9: 160 | K9: 1000 | L9: 50 | M9: 75 | N9: =SUM(H9:M9) -> 1435 | O9: N/A | P9: 2500 | Q9: — | R9: =IFERROR(N9+IF(ISNUMBER(O9),O9,0)+IF(ISNUMBER(P9),P9,0),"") -> 3935 | S9: Kaifu
A10: Incheon-Manzanillo | B10: WOORY | C10: Saltillo | D10: INCHEON | E10: MANZANILLO | F10: CIF | G10: 1 | H10: 70 | I10: 35 | J10: 145 | K10: 350 | L10: 150 | M10: 50 | N10: =SUM(H10:M10) -> 800 | O10: N/A | P10: 2800 | Q10: — | R10: =IFERROR(N10+IF(ISNUMBER(O10),O10,0)+IF(ISNUMBER(P10),P10,0),"") -> 3600 | S10: Kaifu
A11: SHA-Manzanillo (Chao Li) | B11: Jiangsu Chao Li | C11: Puebla | D11: SHA | E11: MANZANILLO | F11: CIF | G11: 2 | H11: 70 | I11: 70 | J11: 145 | K11: 550 | L11: 15 | M11: 60 | N11: =SUM(H11:M11) -> 910 | O11: N/A | P11: 2695 | Q11: — | R11: =IFERROR(N11+IF(ISNUMBER(O11),O11,0)+IF(ISNUMBER(P11),P11,0),"") -> 3605 | S11: Freetrans
A12: SHA-Manzanillo (Yangzhou) | B12: Yangzhou RSL | C12: Puebla | D12: SHA | E12: MANZANILLO | F12: CIF | G12: 1 | H12: 70 | I12: 70 | J12: 145 | K12: 550 | L12: 15 | M12: 60 | N12: =SUM(H12:M12) -> 910 | O12: N/A | P12: 2695 | Q12: — | R12: =IFERROR(N12+IF(ISNUMBER(O12),O12,0)+IF(ISNUMBER(P12),P12,0),"") -> 3605 | S12: Freetrans
A13: SHA-Manzanillo (Yuansheng) | B13: Zhejiang Yuansheng | C13: Puebla | D13: SHA | E13: MANZANILLO | F13: CIF | G13: 1 | H13: 70 | I13: 70 | J13: 145 | K13: 550 | L13: 15 | M13: 60 | N13: =SUM(H13:M13) -> 910 | O13: N/A | P13: 2695 | Q13: — | R13: =IFERROR(N13+IF(ISNUMBER(O13),O13,0)+IF(ISNUMBER(P13),P13,0),"") -> 3605 | S13: Freetrans
A14: SHA-Manzanillo (Huafon Coil) | B14: Shanghai Huafon Coil | C14: Puebla | D14: SHA | E14: MANZANILLO | F14: CIF | G14: 2 | H14: 70 | I14: 70 | J14: 145 | K14: 250 | L14: 15 | M14: 60 | N14: =SUM(H14:M14) -> 610 | O14: N/A | P14: 2695 | Q14: — | R14: =IFERROR(N14+IF(ISNUMBER(O14),O14,0)+IF(ISNUMBER(P14),P14,0),"") -> 3305 | S14: Freetrans
A15: SHA-Manzanillo (ABIC) | B15: Dalian ABIC | C15: Puebla | D15: SHA | E15: MANZANILLO | F15: CIF | G15: 2 | H15: 70 | I15: 70 | J15: 145 | K15: 200 | L15: 15 | M15: 50 | N15: =SUM(H15:M15) -> 550 | O15: N/A | P15: 2695 | Q15: — | R15: =IFERROR(N15+IF(ISNUMBER(O15),O15,0)+IF(ISNUMBER(P15),P15,0),"") -> 3245 | S15: Freetrans
A16: SHA-Manzanillo (Boling) | B16: Chongqing Boling | C16: Puebla | D16: SHA | E16: MANZANILLO | F16: CIF | G16: 0.5 | H16: 70 | I16: 70 | J16: 145 | K16: 1550 | L16: 15 | M16: 60 | N16: =SUM(H16:M16) -> 1910 | O16: N/A | P16: 2695 | Q16: — | R16: =IFERROR(N16+IF(ISNUMBER(O16),O16,0)+IF(ISNUMBER(P16),P16,0),"") -> 4605 | S16: Freetrans
A17: SHA-Manzanillo (AITD) | B17: AITD | C17: Saltillo | D17: SHA | E17: MANZANILLO | F17: CIF | G17: 4 | H17: 70 | I17: 70 | J17: 145 | K17: 350 | L17: 15 | M17: 60 | N17: =SUM(H17:M17) -> 710 | O17: N/A | P17: 2695 | Q17: — | R17: =IFERROR(N17+IF(ISNUMBER(O17),O17,0)+IF(ISNUMBER(P17),P17,0),"") -> 3405 | S17: Freetrans
... A20: SHA-Manzanillo (Shenda) | B20: Changsha Shenda | C20: Saltillo | D20: SHA | E20: MANZANILLO | F20: CIF | G20: 2 | H20: 70 | I20: 70 | J20: 145 | K20: 1500 | L20: 15 | M20: 60 | N20: =SUM(H20:M20) -> 1860 | O20: N/A | P20: 2695 | Q20: — | R20: =IFERROR(N20+IF(ISNUMBER(O20),O20,0)+IF(ISNUMBER(P20),P20,0),"") -> 4555 | S20: Freetrans
A21: AIUS | USA (HOU / Detroit / Savanna) | 5 条航线 | 月需求 8 HQ40
A22: SHA-HOU | B22: AINT - 666 Wenchang Rd, Tongzhou, Nantong | C22: GTZ WAREHOUSE LLC, McALLEN, TX | D22: SHA | E22: HOU | F22: EXW | G22: 2 | H22: 70 | I22: 70 | J22: 140 | K22: 400 | L22: 10 | M22: 70 | O22: 2685 | P22: 3485 | Q22: 8-10 wks | S22: Bestunit
A23: SHA-Detroit | B23: AISH - 108 Chunguang Rd, Minhang, Shanghai | C23: FTZ METRO WAREHOUSE, HIGHLAND PARK, MI | D23: SHA | E23: Detroit | F23: EXW | G23: 0 | H23: 70 | I23: 70 | J23: 140 | K23: 250 | L23: 10 | M23: 70 | N23: =SUM(H23:M23) -> 610 | O23: 885 | P23: 5935 | Q23: — | R23: =IFERROR(N23+IF(ISNUMBER(O23),O23,0)+IF(ISNUMBER(P23),P23,0),"") -> 7430 | S23: Bestunit
A24: Laem-Savanna | B24: AITH (Thailand) | C24: AIUS Baxter, Winchester, TN | D24: Laem Chabang | E24: Savanna | F24: EXW | G24: 0 | H24: 70 | I24: 70 | J24: 140 | K24: 300 | L24: 30 | M24: 70 | N24: =SUM(H24:M24) -> 680 | O24: 2785 | P24: 6200 | Q24: — | R24: =IFERROR(N24+IF(ISNUMBER(O24),O24,0)+IF(ISNUMBER(P24),P24,0),"") -> 9665 | S24: Bestunit
A25: Nhava-Savanna | B25: Divine & Creative (India) | C25: AIUS Baxter, Winchester, TN | D25: Nhava Sheva | E25: Savanna | F25: EXW | G25: 3 | H25: 70 | I25: 80 | J25: 160 | K25: 1000 | L25: 50 | M25: 75 | N25: =SUM(H25:M25) -> 1435 | O25: 2785 | P25: 6500 | Q25: — | R25: =IFERROR(N25+IF(ISNUMBER(O25),O25,0)+IF(ISNUMBER(P25),P25,0),"") -> 10720 | S25: Bestunit
A26: SHA-Savanna | B26: AINT - 666 Wenchang Rd, Tongzhou, Nantong | C26: AIUS Baxter, Winchester, TN | D26: SHA | E26: Savanna | F26: EXW | G26: 3 | H26: 70 | I26: 70 | J26: 140 | K26: 400 | L26: 10 | M26: 70 | N26: =SUM(H26:M26) -> 760 | O26: 2785 | P26: 4849 | Q26: — | R26: =IFERROR(N26+IF(ISNUMBER(O26),O26,0)+IF(ISNUMBER(P26),P26,0),"") -> 8394 | S26: Bestunit
A27: AISH | Asia → SHA (inbound) | 2 条航线 | 月需求 4 HQ40
A28: Bangkok-SHA | B28: DELTA ELECTRONICS (Thailand) | C28: AINT - 666 Wenchang Rd, Tongzhou, Nantong | D28: Bangkok | E28: SHA | F28: EXW | G28: 2 | H28: 70 | I28: 50 | J28: 260 | K28: 325 | L28: 90 | M28: 80 | O28: 600 | P28: 1 | Q28: <18 days | S28: Bestunit
A29: Incheon-SHA | B29: Woory Industrial, Korea | C29: AINT - 666 Wenchang Rd, Tongzhou, Nantong | D29: INCHEON | E29: SHA | F29: EXW | G29: 2 | H29: 70 | I29: 35 | J29: 145 | K29: 350 | L29: 150 | M29: 50 | N29: =SUM(H29:M29) -> 800 | O29: 600 | P29: 1 | Q29: <12 days | R29: =IFERROR(N29+IF(ISNUMBER(O29),O29,0)+IF(ISNUMBER(P29),P29,0),"") -> 1401 | S29: Bestunit/Superchain
A30: AITH | Thailand (Laemchabang) | 5 条航线 | 月需求 11 HQ40
A31: SHA-Laem | B31: AISH - 108 Chunguang Rd, Minhang, Shanghai | C31: AITH, Chonburi 20230 Thailand | D31: SHA | E31: Laemchabang | F31: EXW | G31: 1 | H31: 70 | I31: 70 | J31: 140 | K31: 250 | L31: 10 | M31: 70 | O31: 800 | P31: 490 | Q31: 15-20 days | S31: Rohlig
A32: SHA-Laem (Huafon) | B32: Shanghai Huafon Aluminium Corp. | C32: AITH, Rayong 21140 Thailand | D32: SHA | E32: Laemchabang | F32: EXW | G32: 3 | H32: 70 | I32: 70 | J32: 140 | K32: 250 | L32: 10 | M32: 70 | N32: =SUM(H32:M32) -> 610 | O32: 800 | P32: 490 | Q32: 15-20 days | R32: =IFERROR(N32+IF(ISNUMBER(O32),O32,0)+IF(ISNUMBER(P32),P32,0),"") -> 1900 | S32: Rohlig
A33: Tianjin-Laem | B33: Hyo Seong Electric (Tianjin) | C33: AITH, Chonburi 20230 Thailand | D33: Tianjin | E33: Laemchabang | F33: EXW | G33: 0.5 | H33: 70 | I33: 70 | J33: 140 | K33: 420 | L33: 30 | M33: 70 | N33: =SUM(H33:M33) -> 800 | O33: 800 | P33: 300 | Q33: 18-23 days | R33: =IFERROR(N33+IF(ISNUMBER(O33),O33,0)+IF(ISNUMBER(P33),P33,0),"") -> 1900 | S33: Rohlig
A34: Dubai-Laem | B34: OSE Industries LLC, Dubai | C34: AITH, Rayong 21140 Thailand | D34: Dubai | E34: Laemchabang | F34: EXW | G34: 0.5 | H34: 70 | I34: 70 | J34: 140 | K34: 420 | L34: 30 | M34: 70 | N34: =SUM(H34:M34) -> 800 | O34: 800 | P34: 900 | Q34: 20-25 days | R34: =IFERROR(N34+IF(ISNUMBER(O34),O34,0)+IF(ISNUMBER(P34),P34,0),"") -> 2500 | S34: Superchain
A35: Laem-Hamburg | B35: AITH, Rayong 21140 Thailand | C35: AISK, Nitra, Slovakia | D35: Laemchabang | E35: Hamburg | F35: DDP | G35: 6 | H35: 70 | I35: 70 | J35: 140 | K35: 300 | L35: 30 | M35: 70 | N35: =SUM(H35:M35) -> 680 | O35: 2200 | P35: 4800 | Q35: 9-10 wks | R35: =IFERROR(N35+IF(ISNUMBER(O35),O35,0)+IF(ISNUMBER(P35),P35,0),"") -> 7680 | S35: Superchain
A36: AISK | Slovakia (Hamburg) | 3 条航线 | 月需求 4.5 HQ40
A37: SHA-Hamburg | B37: AINT - 666 Wenchang Rd, Tongzhou, Nantong | C37: AISK, Nitra, Slovakia | D37: SHA | E37: Hamburg | F37: EXW | G37: 1 | H37: 70 | I37: 70 | J37: 140 | K37: 400 | L37: 10 | M37: 70 | O37: 2200 | P37: 3635 | Q37: 8-9 wks | S37: Bestunit
A38: Nhava-Hamburg | B38: Divine Tooling | C38: AISK, Nitra, Slovakia | D38: Nhava Sheva | E38: Hamburg | F38: EXW | G38: 3 | H38: 70 | I38: 70 | J38: 140 | K38: 300 | L38: 250 | M38: 70 | N38: =SUM(H38:M38) -> 900 | O38: 2200 | P38: 4500 | Q38: 8-10 wks | R38: =IFERROR(N38+IF(ISNUMBER(O38),O38,0)+IF(ISNUMBER(P38),P38,0),"") -> 7600 | S38: Superchain
A39: Bangkok-Hamburg | B39: Delta Electronics | C39: AISK, Nitra, Slovakia | D39: Bangkok | E39: Hamburg | F39: EXW | G39: 0.5 | H39: 70 | I39: 70 | J39: 140 | K39: 300 | L39: 250 | M39: 70 | N39: =SUM(H39:M39) -> 900 | O39: 2200 | P39: 4500 | Q39: 9-10 wks | R39: =IFERROR(N39+IF(ISNUMBER(O39),O39,0)+IF(ISNUMBER(P39),P39,0),"") -> 7600 | S39: Superchain

Sheet 25.10月
A1: Lane | B1: Consignor | C1: Consignee | D1: POL | E1: POD | F1: Incoterm | G1: HQ40 Demand | H1: Booking Fee | I1: Doc Fee | J1: THC | K1: Loading | L1: Customs | M1: B/L | N1: Local Subtotal | O1: Dest Local Cost | P1: Sea Freight | Q1: Transit Time | R1: Total (USD) | S1: Winning Forwarder
A2: AI-Turkey | Turkey (Izmit) | 2 条航线 | 月需求 18 HQ40
A3: SHA-Izmit | B3: AINT- 666 Wenchang Road, Tongzhou District, Nantong City | C3: AIR INTERNATIONAL TERMAL SİSTEMLERİ A. Ş. ESENTEPE MAH. ALİ KAYA SK. POLAT PLAZA B BLOK NO: 1/1 İÇ KAPI NO:69 ŞİŞLİ/İSTANBUL | D3: SHA | E3: Izmit | F3: DAP | G3: 16 | H3: 70 | I3: 70 | J3: 140 | K3: 400 | L3: 10 | M3: 70 | N3: =SUM(H3:M3) -> 760 | O3: 950 | P3: 2200 | R3: =IFERROR(N3+IF(ISNUMBER(O3),O3,0)+IF(ISNUMBER(P3),P3,0),"") -> 3910 | S3: Holiton
A4: SHA-Izmit | B4: SAI-No. 3 Gaobao Lake East Road, Yubei District, Chongqing | C4: AIR INTERNATIONAL TERMAL SİSTEMLERİ A. Ş. ESENTEPE MAH. ALİ KAYA SK. POLAT PLAZA B BLOK NO: 1/1 İÇ KAPI NO:69 ŞİŞLİ/İSTANBUL | D4: SHA | E4: Izmit | F4: EXW | G4: 2 | H4: 70 | I4: 70 | J4: 140 | K4: 200 | L4: 20 | M4: 50 | N4: =SUM(H4:M4) -> 550 | O4: 950 | P4: 2650 | R4: =IFERROR(N4+IF(ISNUMBER(O4),O4,0)+IF(ISNUMBER(P4),P4,0),"") -> 4150 | S4: Kaifu
A5: AIMX | Mexico (Manzanillo) | 15 条航线 | 月需求 34 HQ40
A6: Laemchabang-Manzanillo | B6: AITH | C6: Puebla + Saltillo | D6: Laemchabang | E6: Manzanillo | F6: CIF | G6: 9 | H6: 70 | I6: 50 | J6: 260 | K6: 250 | L6: 90 | M6: 80 | N6: =SUM(H6:M6) -> 800 | O6: N/A | P6: 2550 | R6: =IFERROR(N6+IF(ISNUMBER(O6),O6,0)+IF(ISNUMBER(P6),P6,0),"") -> 3350 | S6: Bondex
A7: Bangkok-Manzanillo | B7: DELTA | C7: Saltillo | D7: Bangkok | E7: Manzanillo | F7: CIF | G7: 4 | H7: 70 | I7: 50 | J7: 260 | K7: 325 | L7: 90 | M7: 80 | N7: =SUM(H7:M7) -> 875 | O7: N/A | P7: 2550 | R7: =IFERROR(N7+IF(ISNUMBER(O7),O7,0)+IF(ISNUMBER(P7),P7,0),"") -> 3425 | S7: Bondex
A8: Laemchabang-Manzanillo | B8: TNC | C8: Puebla | D8: Laemchabang | E8: Manzanillo | F8: CIF | G8: 0.5 | H8: 70 | I8: 50 | J8: 260 | K8: 250 | L8: 90 | M8: 80 | N8: =SUM(H8:M8) -> 800 | O8: N/A | P8: 2550 | R8: =IFERROR(N8+IF(ISNUMBER(O8),O8,0)+IF(ISNUMBER(P8),P8,0),"") -> 3350 | S8: Bondex
A9: Nhava Sheva-Manzanillo | B9: Creative Components | C9: Saltillo | D9: Nhava Sheva | E9: Manzanillo | F9: CIF | G9: 2 | H9: 70 | I9: 80 | J9: 160 | K9: 1000 | L9: 50 | M9: 75 | N9: =SUM(H9:M9) -> 1435 | O9: N/A | P9: 2500 | R9: =IFERROR(N9+IF(ISNUMBER(O9),O9,0)+IF(ISNUMBER(P9),P9,0),"") -> 3935 | S9: Kaifu
A10: Incheon-Manzanillo | B10: WOORY | C10: Saltillo | D10: Incheon | E10: Manzanillo | F10: CIF | G10: 1 | H10: 70 | I10: 35 | J10: 145 | K10: 350 | L10: 150 | M10: 50 | N10: =SUM(H10:M10) -> 800 | O10: N/A | P10: 2500 | R10: =IFERROR(N10+IF(ISNUMBER(O10),O10,0)+IF(ISNUMBER(P10),P10,0),"") -> 3300 | S10: Bondex
A11: SHA-Manzanillo | B11: Jiangsu Chao Li | C11: Puebla | D11: SHA | E11: Manzanillo | F11: FOB | G11: 2 | H11: 70 | I11: 70 | J11: 145 | K11: 550 | L11: 15 | M11: 60 | N11: =SUM(H11:M11) -> 910 | O11: N/A | P11: 2250 | R11: =IFERROR(N11+IF(ISNUMBER(O11),O11,0)+IF(ISNUMBER(P11),P11,0),"") -> 3160 | S11: Bondex
A12: SHA-Manzanillo | B12: Yangzhou RSL | C12: Puebla | D12: SHA | E12: Manzanillo | F12: CIF | G12: 1 | H12: 70 | I12: 70 | J12: 145 | K12: 550 | L12: 15 | M12: 60 | N12: =SUM(H12:M12) -> 910 | O12: N/A | P12: 2250 | R12: =IFERROR(N12+IF(ISNUMBER(O12),O12,0)+IF(ISNUMBER(P12),P12,0),"") -> 3160 | S12: Bondex
A13: SHA-Manzanillo | B13: Zhejiang Yuansheng | C13: Puebla | D13: SHA | E13: Manzanillo | F13: CIF | G13: 1 | H13: 70 | I13: 70 | J13: 145 | K13: 550 | L13: 15 | M13: 60 | N13: =SUM(H13:M13) -> 910 | O13: N/A | P13: 2250 | R13: =IFERROR(N13+IF(ISNUMBER(O13),O13,0)+IF(ISNUMBER(P13),P13,0),"") -> 3160 | S13: Bondex
A14: SHA-Manzanillo | B14: Shanghai Huafon Coil | C14: Puebla | D14: SHA | E14: Manzanillo | F14: CIF | G14: 2 | H14: 70 | I14: 70 | J14: 145 | K14: 250 | L14: 15 | M14: 60 | N14: =SUM(H14:M14) -> 610 | O14: N/A | P14: 2250 | R14: =IFERROR(N14+IF(ISNUMBER(O14),O14,0)+IF(ISNUMBER(P14),P14,0),"") -> 2860 | S14: Bondex
A15: SHA-Manzanillo | B15: Dalian ABIC | C15: Puebla | D15: SHA | E15: Manzanillo | F15: CIF | G15: 2 | H15: 70 | I15: 70 | J15: 145 | K15: 200 | L15: 15 | M15: 50 | N15: =SUM(H15:M15) -> 550 | O15: N/A | P15: 2300 | R15: =IFERROR(N15+IF(ISNUMBER(O15),O15,0)+IF(ISNUMBER(P15),P15,0),"") -> 2850 | S15: Kaifu
A16: SHA-Manzanillo | B16: Chongqing Boling | C16: Puebla | D16: SHA | E16: Manzanillo | F16: CIF | G16: 0.5 | H16: 70 | I16: 70 | J16: 145 | K16: 1550 | L16: 15 | M16: 60 | N16: =SUM(H16:M16) -> 1910 | O16: N/A | P16: 2300 | R16: =IFERROR(N16+IF(ISNUMBER(O16),O16,0)+IF(ISNUMBER(P16),P16,0),"") -> 4210 | S16: Kaifu
A17: SHA-Manzanillo | B17: AITD | C17: Saltillo | D17: SHA | E17: Manzanillo | F17: CIF | G17: 4 | H17: 70 | I17: 70 | J17: 145 | K17: 350 | L17: 15 | M17: 60 | N17: =SUM(H17:M17) -> 710 | O17: N/A | P17: 2250 | R17: =IFERROR(N17+IF(ISNUMBER(O17),O17,0)+IF(ISNUMBER(P17),P17,0),"") -> 2960 | S17: Bondex
... A20: SHA-Manzanillo | B20: Changsha Shenda | C20: Saltillo | D20: SHA | E20: Manzanillo | F20: CIF | G20: 2 | H20: 70 | I20: 70 | J20: 145 | K20: 1500 | L20: 15 | M20: 60 | N20: =SUM(H20:M20) -> 1860 | O20: N/A | P20: 2300 | R20: =IFERROR(N20+IF(ISNUMBER(O20),O20,0)+IF(ISNUMBER(P20),P20,0),"") -> 4160 | S20: Kaifu
A21: AIUS | USA (HOU / Detroit / Savanna) | 5 条航线 | 月需求 10 HQ40
A22: SHA-HOU | B22: AINT- 666 Wenchang Road, Tongzhou District, Nantong City | C22: Air International Thermal System-c/o GTZ WAREHOUSE LLC-662 SOUTH 33rd STREET, BUILDING-J, McALLEN, TX 78503 | D22: SHA | E22: HOU | F22: EXW | G22: 2 | H22: 70 | I22: 70 | J22: 140 | K22: 400 | L22: 10 | M22: 70 | N22: =SUM(H22:M22) -> 760 | O22: 2685 | P22: 2886 | R22: =IFERROR(N22+IF(ISNUMBER(O22),O22,0)+IF(ISNUMBER(P22),P22,0),"") -> 6331 | S22: Bestunit
A23: SHA-Detroit | B23: AISH-108 Chunguang Road, Minhang District, Shanghai | C23: Air International Thermal Systems-c/o FTZ METRO WAREHOUSE-1200 E. McNICHOLS RD, HIGHLAND PARK, MI 48203 | D23: SHA | E23: Detroit | F23: EXW | G23: 2 | H23: 70 | I23: 70 | J23: 140 | K23: 250 | L23: 10 | M23: 70 | N23: =SUM(H23:M23) -> 610 | O23: 885 | P23: 3979 | R23: =IFERROR(N23+IF(ISNUMBER(O23),O23,0)+IF(ISNUMBER(P23),P23,0),"") -> 5474 | S23: Bestunit
A24: Laem Chabang-Savanna | B24: Air International Thermal Systems (Thailand) Ltd. (Head Office) 500/46 Moo 3, WHA Eastern Seaboard Industrial Estate 1 Tambol Tasit, Amphur Pluak Daeng, Rayong 21140 Thailand | C24: Air International Thermal Systems 466 Baxter Lane Winchester, TN, USA, 37398 | D24: Laem Chabang | E24: Savanna | F24: EXW | G24: 0 | H24: 70 | I24: 70 | J24: 140 | K24: 300 | L24: 30 | M24: 70 | N24: =SUM(H24:M24) -> 680 | O24: 2785 | P24: 3770 | R24: =IFERROR(N24+IF(ISNUMBER(O24),O24,0)+IF(ISNUMBER(P24),P24,0),"") -> 7235 | S24: Bestunit
A25: Nhava Sheva-Savanna | B25: Divine & Creative from India | C25: Air International Thermal Systems 466 Baxter Lane Winchester, TN, USA, 37398 | D25: Nhava Sheva | E25: Savanna | F25: EXW | G25: 3 | H25: 70 | I25: 80 | J25: 160 | K25: 1000 | L25: 50 | M25: 75 | N25: =SUM(H25:M25) -> 1435 | O25: 2785 | P25: 4737 | R25: =IFERROR(N25+IF(ISNUMBER(O25),O25,0)+IF(ISNUMBER(P25),P25,0),"") -> 8957 | S25: Bestunit
A26: SHA-Savanna | B26: AINT- 666 Wenchang Road, Tongzhou District, Nantong City | C26: Air International Thermal Systems 466 Baxter Lane Winchester, TN, USA, 37398 | D26: SHA | E26: Savanna | F26: EXW | G26: 3 | H26: 70 | I26: 70 | J26: 140 | K26: 400 | L26: 10 | M26: 70 | N26: =SUM(H26:M26) -> 760 | O26: 2785 | P26: 3168 | R26: =IFERROR(N26+IF(ISNUMBER(O26),O26,0)+IF(ISNUMBER(P26),P26,0),"") -> 6713 | S26: Bestunit
A27: AISH | Asia → SHA (inbound) | 2 条航线 | 月需求 1 HQ40
A28: Bangkok-SHA | B28: DELTA ELECTRONICS (THAILAND) PUBLIC COMPANY LIMITED 111 MOO 9, BANGNA-TRAD RD., TAMBOL BANGWUA AMPHUR BANGPAKONG CHACHOENGSAO, 24180 THAILAND | C28: AINT- 666 Wenchang Road, Tongzhou District, Nantong City | D28: Bangkok | E28: SHA | F28: EXW | G28: 0 | H28: 70 | I28: 50 | J28: 260 | K28: 325 | L28: 90 | M28: 80 | N28: =SUM(H28:M28) -> 875 | O28: 600 | P28: 1 | R28: =IFERROR(N28+IF(ISNUMBER(O28),O28,0)+IF(ISNUMBER(P28),P28,0),"") -> 1476 | S28: Superchain
A29: Incheon-SHA | B29: Woory Industrial Co., Ltd #531, Jigok-dong, Kihung-gu Yongin-city, Kyonggi-Do, Korea | C29: AINT- 666 Wenchang Road, Tongzhou District, Nantong City | D29: Incheon | E29: SHA | F29: EXW | G29: 1 | H29: 70 | I29: 35 | J29: 145 | K29: 350 | L29: 150 | M29: 50 | N29: =SUM(H29:M29) -> 800 | O29: 600 | P29: 1 | R29: =IFERROR(N29+IF(ISNUMBER(O29),O29,0)+IF(ISNUMBER(P29),P29,0),"") -> 1401 | S29: Superchain
A30: AITH | Thailand (Laemchabang) | 5 条航线 | 月需求 11 HQ40
A31: SHA-Laemchabang | B31: Air International (Shanghai) Co., Ltd. No. 108 Chunguang Road, XinZhuang Industrial Zone, Minhang, Shanghai P.R. China 201108 | C31: Air International Thermal Systems (Thailand) Ltd. 41/17,18,19 MOO 8, T.BOWIN, A.SRIRACHA, CHONBURI, 20230 THAILAND | D31: SHA | E31: Laemchabang | F31: EXW | G31: 1 | H31: 70 | I31: 70 | J31: 140 | K31: 250 | L31: 10 | M31: 70 | N31: =SUM(H31:M31) -> 610 | O31: 800 | P31: 395 | R31: =IFERROR(N31+IF(ISNUMBER(O31),O31,0)+IF(ISNUMBER(P31),P31,0),"") -> 1805 | S31: Rohlig
A32: SHA-Laemchabang | B32: Shanghai Huafon Aluminium Corp. 1111# Yuegong Road, Jinshan District, Shanghai 201506 | C32: Air International Thermal Systems (Thailand) Ltd. 500/46 Moo 3, WHA Eastern Seaboard Industrial Estate 1, T. Tasit, A. Pluekdaeng, Rayong 21140 | D32: SHA | E32: Laemchabang | F32: EXW | G32: 3 | H32: 70 | I32: 70 | J32: 140 | K32: 250 | L32: 10 | M32: 70 | N32: =SUM(H32:M32) -> 610 | O32: 800 | P32: 420 | R32: =IFERROR(N32+IF(ISNUMBER(O32),O32,0)+IF(ISNUMBER(P32),P32,0),"") -> 1830 | S32: Rohlig
A33: Tianjin-Laemchabang | B33: Hyo Seong Electric (Toanjin) Co., Ltd No.99, Xi San Dao, Tianjin Airport Industrial Park, TPFTZ, Tianjin, P.R. China | C33: Air International Thermal Systems (Thailand) Ltd. 41/17,18,19 MOO 8, T.BOWIN, A.SRIRACHA, CHONBURI, 20230 THAILAND | D33: Tianjin | E33: Laemchabang | F33: EXW | G33: 0.5 | H33: 70 | I33: 70 | J33: 140 | K33: 420 | L33: 30 | M33: 70 | N33: =SUM(H33:M33) -> 800 | O33: 800 | P33: 205 | R33: =IFERROR(N33+IF(ISNUMBER(O33),O33,0)+IF(ISNUMBER(P33),P33,0),"") -> 1805 | S33: Rohlig
A34: Dubai-Laemchabang | B34: OSE Industries LLC. Dubai Industrial Park, Office#103, First Floor, Building 1, Dubai Industrial City, Dubai, UAE, Post Box 126344 | C34: Air International Thermal Systems (Thailand) Ltd. 500/46 Moo 3, WHA Eastern Seaboard Industrial Estate 1, T. Tasit, A. Pluekdaeng, Rayong 21140 | D34: Dubai | E34: Laemchabang | F34: EXW | G34: 0.5 | H34: 70 | I34: 70 | J34: 140 | K34: 420 | L34: 30 | M34: 70 | N34: =SUM(H34:M34) -> 800 | O34: 800 | P34: 400 | R34: =IFERROR(N34+IF(ISNUMBER(O34),O34,0)+IF(ISNUMBER(P34),P34,0),"") -> 2000 | S34: Bondex
A35: Laemchabang-Hamburg | B35: Air International Thermal Systems (Thailand) Ltd. 500/46 Moo 3, WHA Eastern Seaboard Industrial Estate 1, T. Tasit, A. Pluekdaeng, Rayong 21140 | C35: Air International Thermal (Slovakia) s.r.o. Prologis Park Nitra, DC3 Cez panske 4289/9, 949 01 Nitra, Slovakia | D35: Laemchabang | E35: Hamburg | F35: DDP | G35: 6 | H35: 70 | I35: 70 | J35: 140 | K35: 300 | L35: 30 | M35: 70 | N35: =SUM(H35:M35) -> 680 | O35: 2200 | P35: 2340 | R35: =IFERROR(N35+IF(ISNUMBER(O35),O35,0)+IF(ISNUMBER(P35),P35,0),"") -> 5220 | S35: Bondex
A36: AISK | Slovakia (Hamburg) | 3 条航线 | 月需求 4.5 HQ40
A37: SHA-Hamburg | B37: AINT- 666 Wenchang Road, Tongzhou District, Nantong City, China | C37: Air International Thermal (Slovakia) s.r.o. Prologis Park Nitra, DC3 Cez panske 4289/9, 949 01 Nitra, Slovakia | D37: SHA | E37: Hamburg | F37: EXW | G37: 1 | H37: 70 | I37: 70 | J37: 140 | K37: 400 | L37: 10 | M37: 70 | N37: =SUM(H37:M37) -> 760 | O37: 2200 | P37: 1990 | R37: =IFERROR(N37+IF(ISNUMBER(O37),O37,0)+IF(ISNUMBER(P37),P37,0),"") -> 4950 | S37: Bondex
A38: Nhava Sheva-Hamburg | B38: Divine tooling | C38: Air International Thermal (Slovakia) s.r.o. Prologis Park Nitra, DC3 Cez panske 4289/9, 949 01 Nitra, Slovakia | D38: Nhava Sheva | E38: Hamburg | F38: EXW | G38: 3 | H38: 70 | I38: 70 | J38: 140 | K38: 300 | L38: 250 | M38: 70 | N38: =SUM(H38:M38) -> 900 | O38: 2200 | P38: 1590 | R38: =IFERROR(N38+IF(ISNUMBER(O38),O38,0)+IF(ISNUMBER(P38),P38,0),"") -> 4690 | S38: Bondex
A39: Bangkok-Hamburg | B39: Delta Electronics | C39: Air International Thermal (Slovakia) s.r.o. Prologis Park Nitra, DC3 Cez panske 4289/9, 949 01 Nitra, Slovakia | D39: Bangkok | E39: Hamburg | F39: EXW | G39: 0.5 | H39: 70 | I39: 70 | J39: 140 | K39: 300 | L39: 250 | M39: 70 | N39: =SUM(H39:M39) -> 900 | O39: 2200 | P39: 1590 | R39: =IFERROR(N39+IF(ISNUMBER(O39),O39,0)+IF(ISNUMBER(P39),P39,0),"") -> 4690 | S39: Bondex

Sheet 25.11月
A1: Lane | B1: Consignor | C1: Consignee | D1: POL | E1: POD | F1: Incoterm | G1: HQ40 Demand | H1: Booking Fee | I1: Doc Fee | J1: THC | K1: Loading | L1: Customs | M1: B/L | N1: Local Subtotal | O1: Dest Local Cost | P1: Sea Freight | Q1: Transit Time | R1: Total (USD) | S1: Winning Forwarder
A2: AI-Turkey | Turkey (Izmit) | 2 条航线 | 月需求 22 HQ40
A3: SHA-Izmit | B3: AINT- 666 Wenchang Road, Tongzhou District, Nantong City | C3: AIR INTERNATIONAL TERMAL SİSTEMLERİ A. Ş. ESENTEPE MAH. ALİ KAYA SK. POLAT PLAZA B BLOK NO: 1/1 İÇ KAPI NO:69 ŞİŞLİ/İSTANBUL | D3: SHA | E3: Izmit | F3: DAP | G3: 18 | H3: 70 | I3: 70 | J3: 140 | K3: 400 | L3: 10 | M3: 70 | N3: =SUM(H3:M3) -> 760 | O3: 950 | P3: 2145 | R3: =IFERROR(N3+IF(ISNUMBER(O3),O3,0)+IF(ISNUMBER(P3),P3,0),"") -> 3855 | S3: Holiton 3 + Bestunit 15
A4: SHA-Izmit | B4: SAI-No. 3 Gaobao Lake East Road, Yubei District, Chongqing | C4: AIR INTERNATIONAL TERMAL SİSTEMLERİ A. Ş. ESENTEPE MAH. ALİ KAYA SK. POLAT PLAZA B BLOK NO: 1/1 İÇ KAPI NO:69 ŞİŞLİ/İSTANBUL | D4: SHA | E4: Izmit | F4: EXW | G4: 4 | H4: 70 | I4: 70 | J4: 140 | K4: 200 | L4: 20 | M4: 50 | N4: =SUM(H4:M4) -> 550 | O4: 950 | P4: 3650 | R4: =IFERROR(N4+IF(ISNUMBER(O4),O4,0)+IF(ISNUMBER(P4),P4,0),"") -> 5150 | S4: Bestunit
A5: AIMX | Mexico (Manzanillo) | 15 条航线 | 月需求 31 HQ40
A6: Laemchabang-Manzanillo | B6: AITH | C6: Puebla + Saltillo | D6: Laemchabang | E6: Manzanillo | F6: CIF | G6: 9 | H6: 70 | I6: 50 | J6: 260 | K6: 250 | L6: 90 | M6: 80 | N6: =SUM(H6:M6) -> 800 | O6: N/A | P6: 2350 | R6: =IFERROR(N6+IF(ISNUMBER(O6),O6,0)+IF(ISNUMBER(P6),P6,0),"") -> 3150 | S6: Freetrans
A7: Bangkok-Manzanillo | B7: DELTA | C7: Saltillo | D7: Bangkok | E7: Manzanillo | F7: CIF | G7: 2 | H7: 70 | I7: 50 | J7: 260 | K7: 325 | L7: 90 | M7: 80 | N7: =SUM(H7:M7) -> 875 | O7: N/A | P7: 2100 | R7: =IFERROR(N7+IF(ISNUMBER(O7),O7,0)+IF(ISNUMBER(P7),P7,0),"") -> 2975 | S7: Kaifu
A8: Laemchabang-Manzanillo | B8: TNC | C8: Puebla | D8: Laemchabang | E8: Manzanillo | F8: CIF | G8: 0.5 | H8: 70 | I8: 50 | J8: 260 | K8: 250 | L8: 90 | M8: 80 | N8: =SUM(H8:M8) -> 800 | O8: N/A | P8: 2250 | R8: =IFERROR(N8+IF(ISNUMBER(O8),O8,0)+IF(ISNUMBER(P8),P8,0),"") -> 3050 | S8: Kaifu
A9: Nhava Sheva-Manzanillo | B9: Creative Components | C9: Saltillo | D9: Nhava Sheva | E9: Manzanillo | F9: CIF | G9: 1 | H9: 70 | I9: 80 | J9: 160 | K9: 1000 | L9: 50 | M9: 75 | N9: =SUM(H9:M9) -> 1435 | O9: N/A | P9: 2500 | R9: =IFERROR(N9+IF(ISNUMBER(O9),O9,0)+IF(ISNUMBER(P9),P9,0),"") -> 3935 | S9: Kaifu
A10: Incheon-Manzanillo | B10: WOORY | C10: Saltillo | D10: Incheon | E10: Manzanillo | F10: CIF | G10: 1 | H10: 70 | I10: 35 | J10: 145 | K10: 350 | L10: 150 | M10: 50 | N10: =SUM(H10:M10) -> 800 | O10: N/A | P10: 2390 | R10: =IFERROR(N10+IF(ISNUMBER(O10),O10,0)+IF(ISNUMBER(P10),P10,0),"") -> 3190 | S10: Kaifu
A11: SHA-Manzanillo | B11: Jiangsu Chao Li | C11: Puebla | D11: SHA | E11: Manzanillo | F11: CIF | G11: 2 | H11: 70 | I11: 70 | J11: 145 | K11: 550 | L11: 15 | M11: 60 | N11: =SUM(H11:M11) -> 910 | O11: N/A | P11: 1790 | R11: =IFERROR(N11+IF(ISNUMBER(O11),O11,0)+IF(ISNUMBER(P11),P11,0),"") -> 2700 | S11: Kaifu
A12: SHA-Manzanillo | B12: Yangzhou RSL | C12: Puebla | D12: SHA | E12: Manzanillo | F12: CIF | G12: 1 | H12: 70 | I12: 70 | J12: 145 | K12: 550 | L12: 15 | M12: 60 | N12: =SUM(H12:M12) -> 910 | O12: N/A | P12: 1800 | R12: =IFERROR(N12+IF(ISNUMBER(O12),O12,0)+IF(ISNUMBER(P12),P12,0),"") -> 2710 | S12: Kaifu
A13: SHA-Manzanillo | B13: Zhejiang Yuansheng | C13: Puebla | D13: SHA | E13: Manzanillo | F13: CIF | G13: 1 | H13: 70 | I13: 70 | J13: 145 | K13: 550 | L13: 15 | M13: 60 | N13: =SUM(H13:M13) -> 910 | O13: N/A | P13: 1800 | R13: =IFERROR(N13+IF(ISNUMBER(O13),O13,0)+IF(ISNUMBER(P13),P13,0),"") -> 2710 | S13: Kaifu
A14: SHA-Manzanillo | B14: Shanghai Huafon Coil | C14: Puebla | D14: SHA | E14: Manzanillo | F14: CIF | G14: 2 | H14: 70 | I14: 70 | J14: 145 | K14: 250 | L14: 15 | M14: 60 | N14: =SUM(H14:M14) -> 610 | O14: N/A | P14: 1800 | R14: =IFERROR(N14+IF(ISNUMBER(O14),O14,0)+IF(ISNUMBER(P14),P14,0),"") -> 2410 | S14: Kaifu
A15: SHA-Manzanillo | B15: Dalian ABIC | C15: Puebla | D15: SHA | E15: Manzanillo | F15: CIF | G15: 2 | H15: 70 | I15: 70 | J15: 145 | K15: 200 | L15: 15 | M15: 50 | N15: =SUM(H15:M15) -> 550 | O15: N/A | P15: 1770 | R15: =IFERROR(N15+IF(ISNUMBER(O15),O15,0)+IF(ISNUMBER(P15),P15,0),"") -> 2320 | S15: Kaifu
A16: SHA-Manzanillo | B16: Chongqing Boling | C16: Puebla | D16: SHA | E16: Manzanillo | F16: CIF | G16: 0.5 | H16: 70 | I16: 70 | J16: 145 | K16: 1550 | L16: 15 | M16: 60 | N16: =SUM(H16:M16) -> 1910 | O16: N/A | P16: 1800 | R16: =IFERROR(N16+IF(ISNUMBER(O16),O16,0)+IF(ISNUMBER(P16),P16,0),"") -> 3710 | S16: Kaifu
A17: SHA-Manzanillo | B17: AITD | C17: Saltillo | D17: SHA | E17: Manzanillo | F17: CIF | G17: 4 | H17: 70 | I17: 70 | J17: 145 | K17: 350 | L17: 15 | M17: 60 | N17: =SUM(H17:M17) -> 710 | O17: N/A | P17: 1800 | R17: =IFERROR(N17+IF(ISNUMBER(O17),O17,0)+IF(ISNUMBER(P17),P17,0),"") -> 2510 | S17: Kaifu
... A20: SHA-Manzanillo | B20: Changsha Shenda | C20: Saltillo | D20: SHA | E20: Manzanillo | F20: CIF | G20: 2 | H20: 70 | I20: 70 | J20: 145 | K20: 1500 | L20: 15 | M20: 60 | N20: =SUM(H20:M20) -> 1860 | O20: N/A | P20: 1800 | R20: =IFERROR(N20+IF(ISNUMBER(O20),O20,0)+IF(ISNUMBER(P20),P20,0),"") -> 3660 | S20: Kaifu
A21: AIUS | USA (HOU / Detroit / Savanna) | 5 条航线 | 月需求 12 HQ40
A22: SHA-HOU | B22: AINT- 666 Wenchang Road, Tongzhou District, Nantong City | C22: Air International Thermal System-c/o GTZ WAREHOUSE LLC-662 SOUTH 33rd STREET, BUILDING-J, McALLEN, TX 78503 | D22: SHA | E22: HOU | F22: EXW | G22: 2 | H22: 70 | I22: 70 | J22: 140 | K22: 400 | L22: 10 | M22: 70 | N22: =SUM(H22:M22) -> 760 | O22: 2685 | P22: 2600 | R22: =IFERROR(N22+IF(ISNUMBER(O22),O22,0)+IF(ISNUMBER(P22),P22,0),"") -> 6045 | S22: Kaifu
A23: SHA-Detroit | B23: AISH-108 Chunguang Road, Minhang District, Shanghai | C23: Air International Thermal Systems-c/o FTZ METRO WAREHOUSE-1200 E. McNICHOLS RD, HIGHLAND PARK, MI 48203 | D23: SHA | E23: Detroit | F23: EXW | G23: 1 | H23: 70 | I23: 70 | J23: 140 | K23: 250 | L23: 10 | M23: 70 | N23: =SUM(H23:M23) -> 610 | O23: 885 | P23: 4050 | R23: =IFERROR(N23+IF(ISNUMBER(O23),O23,0)+IF(ISNUMBER(P23),P23,0),"") -> 5545 | S23: Kaifu
A24: Laem Chabang-Savanna | B24: Air International Thermal Systems (Thailand) Ltd. (Head Office) 500/46 Moo 3, WHA Eastern Seaboard Industrial Estate 1 Tambol Tasit, Amphur Pluak Daeng, Rayong 21140 Thailand | C24: Air International Thermal Systems 466 Baxter Lane Winchester, TN, USA, 37398 | D24: Laem Chabang | E24: Savanna | F24: EXW | G24: 3 | H24: 70 | I24: 70 | J24: 140 | K24: 300 | L24: 30 | M24: 70 | N24: =SUM(H24:M24) -> 680 | O24: 2785 | P24: 2495 | R24: =IFERROR(N24+IF(ISNUMBER(O24),O24,0)+IF(ISNUMBER(P24),P24,0),"") -> 5960 | S24: Freetrans
A25: Nhava Sheva-Savanna | B25: Divine & Creative from India | C25: Air International Thermal Systems 466 Baxter Lane Winchester, TN, USA, 37398 | D25: Nhava Sheva | E25: Savanna | F25: EXW | G25: 3 | H25: 70 | I25: 80 | J25: 160 | K25: 1000 | L25: 50 | M25: 75 | N25: =SUM(H25:M25) -> 1435 | O25: 2785 | P25: 2485 | R25: =IFERROR(N25+IF(ISNUMBER(O25),O25,0)+IF(ISNUMBER(P25),P25,0),"") -> 6705 | S25: Freetrans
A26: SHA-Savanna | B26: AINT- 666 Wenchang Road, Tongzhou District, Nantong City | C26: Air International Thermal Systems 466 Baxter Lane Winchester, TN, USA, 37398 | D26: SHA | E26: Savanna | F26: EXW | G26: 3 | H26: 70 | I26: 70 | J26: 140 | K26: 400 | L26: 10 | M26: 70 | N26: =SUM(H26:M26) -> 760 | O26: 2785 | P26: 2250 | R26: =IFERROR(N26+IF(ISNUMBER(O26),O26,0)+IF(ISNUMBER(P26),P26,0),"") -> 5795 | S26: Freetrans
A27: AISH | Asia → SHA (inbound) | 2 条航线 | 月需求 3 HQ40
A28: Bangkok-SHA | B28: DELTA ELECTRONICS (THAILAND) PUBLIC COMPANY LIMITED 111 MOO 9, BANGNA-TRAD RD., TAMBOL BANGWUA AMPHUR BANGPAKONG CHACHOENGSAO, 24180 THAILAND | C28: AINT- 666 Wenchang Road, Tongzhou District, Nantong City | D28: Bangkok | E28: SHA | F28: EXW | G28: 2 | H28: 70 | I28: 50 | J28: 260 | K28: 325 | L28: 90 | M28: 80 | N28: =SUM(H28:M28) -> 875 | O28: 600 | P28: 1 | R28: =IFERROR(N28+IF(ISNUMBER(O28),O28,0)+IF(ISNUMBER(P28),P28,0),"") -> 1476 | S28: Superchain
A29: Incheon-SHA | B29: Woory Industrial Co., Ltd #531, Jigok-dong, Kihung-gu Yongin-city, Kyonggi-Do, Korea | C29: AINT- 666 Wenchang Road, Tongzhou District, Nantong City | D29: Incheon | E29: SHA | F29: EXW | G29: 1 | H29: 70 | I29: 35 | J29: 145 | K29: 350 | L29: 150 | M29: 50 | N29: =SUM(H29:M29) -> 800 | O29: 600 | P29: 1 | R29: =IFERROR(N29+IF(ISNUMBER(O29),O29,0)+IF(ISNUMBER(P29),P29,0),"") -> 1401 | S29: Superchain
A30: AITH | Thailand (Laemchabang) | 5 条航线 | 月需求 11 HQ40
A31: SHA-Laemchabang | B31: Air International (Shanghai) Co., Ltd. No. 108 Chunguang Road, XinZhuang Industrial Zone, Minhang, Shanghai P.R. China 201108 | C31: Air International Thermal Systems (Thailand) Ltd. 41/17,18,19 MOO 8, T.BOWIN, A.SRIRACHA, CHONBURI, 20230 THAILAND | D31: SHA | E31: Laemchabang | F31: EXW | G31: 1 | H31: 70 | I31: 70 | J31: 140 | K31: 250 | L31: 10 | M31: 70 | N31: =SUM(H31:M31) -> 610 | O31: 800 | P31: 395 | R31: =IFERROR(N31+IF(ISNUMBER(O31),O31,0)+IF(ISNUMBER(P31),P31,0),"") -> 1805 | S31: Rohlig
A32: SHA-Laemchabang | B32: Shanghai Huafon Aluminium Corp. 1111# Yuegong Road, Jinshan District, Shanghai 201506 | C32: Air International Thermal Systems (Thailand) Ltd. 500/46 Moo 3, WHA Eastern Seaboard Industrial Estate 1, T. Tasit, A. Pluekdaeng, Rayong 21140 | D32: SHA | E32: Laemchabang | F32: EXW | G32: 3 | H32: 70 | I32: 70 | J32: 140 | K32: 250 | L32: 10 | M32: 70 | N32: =SUM(H32:M32) -> 610 | O32: 800 | P32: 420 | R32: =IFERROR(N32+IF(ISNUMBER(O32),O32,0)+IF(ISNUMBER(P32),P32,0),"") -> 1830 | S32: Rohlig
A33: Tianjin-Laemchabang | B33: Hyo Seong Electric (Toanjin) Co., Ltd No.99, Xi San Dao, Tianjin Airport Industrial Park, TPFTZ, Tianjin, P.R. China | C33: Air International Thermal Systems (Thailand) Ltd. 41/17,18,19 MOO 8, T.BOWIN, A.SRIRACHA, CHONBURI, 20230 THAILAND | D33: Tianjin | E33: Laemchabang | F33: EXW | G33: 0.5 | H33: 70 | I33: 70 | J33: 140 | K33: 420 | L33: 30 | M33: 70 | N33: =SUM(H33:M33) -> 800 | O33: 800 | P33: 205 | R33: =IFERROR(N33+IF(ISNUMBER(O33),O33,0)+IF(ISNUMBER(P33),P33,0),"") -> 1805 | S33: Rohlig
A34: Dubai-Laemchabang | B34: OSE Industries LLC. Dubai Industrial Park, Office#103, First Floor, Building 1, Dubai Industrial City, Dubai, UAE, Post Box 126344 | C34: Air International Thermal Systems (Thailand) Ltd. 500/46 Moo 3, WHA Eastern Seaboard Industrial Estate 1, T. Tasit, A. Pluekdaeng, Rayong 21140 | D34: Dubai | E34: Laemchabang | F34: EXW | G34: 0.5 | H34: 70 | I34: 70 | J34: 140 | K34: 420 | L34: 30 | M34: 70 | N34: =SUM(H34:M34) -> 800 | O34: 800 | P34: 1640 | R34: =IFERROR(N34+IF(ISNUMBER(O34),O34,0)+IF(ISNUMBER(P34),P34,0),"") -> 3240 | S34: 当地自行招标
A35: Laemchabang-Hamburg | B35: Air International Thermal Systems (Thailand) Ltd. 500/46 Moo 3, WHA Eastern Seaboard Industrial Estate 1, T. Tasit, A. Pluekdaeng, Rayong 21140 | C35: Air International Thermal (Slovakia) s.r.o. Prologis Park Nitra, DC3 Cez panske 4289/9, 949 01 Nitra, Slovakia | D35: Laemchabang | E35: Hamburg | F35: DDP | G35: 6 | H35: 70 | I35: 70 | J35: 140 | K35: 300 | L35: 30 | M35: 70 | N35: =SUM(H35:M35) -> 680 | O35: 2200 | P35: 2670 | R35: =IFERROR(N35+IF(ISNUMBER(O35),O35,0)+IF(ISNUMBER(P35),P35,0),"") -> 5550 | S35: Rohlig
A36: AISK | Slovakia (Hamburg) | 3 条航线 | 月需求 3.5 HQ40
A37: SHA-Hamburg | B37: AINT- 666 Wenchang Road, Tongzhou District, Nantong City, China | C37: Air International Thermal (Slovakia) s.r.o. Prologis Park Nitra, DC3 Cez panske 4289/9, 949 01 Nitra, Slovakia | D37: SHA | E37: Hamburg | F37: EXW | G37: 1 | H37: 70 | I37: 70 | J37: 140 | K37: 400 | L37: 10 | M37: 70 | N37: =SUM(H37:M37) -> 760 | O37: 2200 | P37: 1890 | R37: =IFERROR(N37+IF(ISNUMBER(O37),O37,0)+IF(ISNUMBER(P37),P37,0),"") -> 4850 | S37: Bondex
A38: Nhava Sheva-Hamburg | B38: Divine tooling | C38: Air International Thermal (Slovakia) s.r.o. Prologis Park Nitra, DC3 Cez panske 4289/9, 949 01 Nitra, Slovakia | D38: Nhava Sheva | E38: Hamburg | F38: EXW | G38: 2 | H38: 70 | I38: 70 | J38: 140 | K38: 300 | L38: 250 | M38: 70 | N38: =SUM(H38:M38) -> 900 | O38: 2200 | P38: 4603 | R38: =IFERROR(N38+IF(ISNUMBER(O38),O38,0)+IF(ISNUMBER(P38),P38,0),"") -> 7703 | S38: 当地自行招标
A39: Bangkok-Hamburg | B39: Delta Electronics | C39: Air International Thermal (Slovakia) s.r.o. Prologis Park Nitra, DC3 Cez panske 4289/9, 949 01 Nitra, Slovakia | D39: Bangkok | E39: Hamburg | F39: EXW | G39: 0.5 | H39: 70 | I39: 70 | J39: 140 | K39: 300 | L39: 250 | M39: 70 | N39: =SUM(H39:M39) -> 900 | O39: 2200 | P39: 5156 | R39: =IFERROR(N39+IF(ISNUMBER(O39),O39,0)+IF(ISNUMBER(P39),P39,0),"") -> 8256 | S39: 当地自行招标

Sheet 25.12月
A1: Lane | B1: Consignor | C1: Consignee | D1: POL | E1: POD | F1: Incoterm | G1: HQ40 Demand | H1: Booking Fee | I1: Doc Fee | J1: THC | K1: Loading | L1: Customs | M1: B/L | N1: Local Subtotal | O1: Dest Local Cost | P1: Sea Freight | Q1: Transit Time | R1: Total (USD) | S1: Winning Forwarder
A2: AI-Turkey | Turkey (Izmit) | 2 条航线 | 月需求 20 HQ40
A3: SHA-Izmit | B3: AINT- 666 Wenchang Road, Tongzhou District, Nantong City | C3: AIR INTERNATIONAL TERMAL SİSTEMLERİ A. Ş. ESENTEPE MAH. ALİ KAYA SK. POLAT PLAZA B BLOK NO: 1/1 İÇ KAPI NO:69 ŞİŞLİ/İSTANBUL | D3: SHA | E3: Izmit | F3: DAP | G3: 16 | H3: 70 | I3: 70 | J3: 140 | K3: 400 | L3: 10 | M3: 70 | N3: =SUM(H3:M3) -> 760 | O3: 950 | P3: 2800 | Q3: 8-10 wks | R3: =IFERROR(N3+IF(ISNUMBER(O3),O3,0)+IF(ISNUMBER(P3),P3,0),"") -> 4510 | S3: Kaifu
A4: SHA-Izmit | B4: SAI-No. 3 Gaobao Lake East Road, Yubei District, Chongqing | C4: AIR INTERNATIONAL TERMAL SİSTEMLERİ A. Ş. ESENTEPE MAH. ALİ KAYA SK. POLAT PLAZA B BLOK NO: 1/1 İÇ KAPI NO:69 ŞİŞLİ/İSTANBUL | D4: SHA | E4: Izmit | F4: EXW | G4: 4 | H4: 70 | I4: 70 | J4: 170 | K4: 250 | L4: 50 | M4: 50 | N4: =SUM(H4:M4) -> 660 | O4: 950 | P4: 4600 | Q4: 9-11 wks | R4: =IFERROR(N4+IF(ISNUMBER(O4),O4,0)+IF(ISNUMBER(P4),P4,0),"") -> 6210 | S4: Kaifu
A5: AIMX | Mexico (Manzanillo) | 16 条航线 | 月需求 31 HQ40
A6: Laemchabang-Manzanillo | B6: AITH | C6: Puebla + Saltillo | D6: Laemchabang | E6: Manzanillo | F6: CIF | G6: 9 | H6: 70 | I6: 50 | J6: 260 | K6: 250 | L6: 90 | M6: 80 | N6: =SUM(H6:M6) -> 800 | O6: N/A | P6: 2048 | Q6: 35-45 days | R6: =IFERROR(N6+IF(ISNUMBER(O6),O6,0)+IF(ISNUMBER(P6),P6,0),"") -> 2848 | S6: Bondex
A7: Bangkok-Manzanillo | B7: DELTA | C7: Saltillo | D7: Bangkok | E7: Manzanillo | F7: CIF | G7: 2 | H7: 70 | I7: 50 | J7: 260 | K7: 325 | L7: 90 | M7: 80 | N7: =SUM(H7:M7) -> 875 | O7: N/A | P7: 2048 | R7: =IFERROR(N7+IF(ISNUMBER(O7),O7,0)+IF(ISNUMBER(P7),P7,0),"") -> 2923 | S7: Bondex
A8: Laemchabang-Manzanillo | B8: TNC | C8: Puebla | D8: Laemchabang | E8: Manzanillo | F8: CIF | G8: 1 | H8: 70 | I8: 50 | J8: 260 | K8: 250 | L8: 90 | M8: 80 | N8: =SUM(H8:M8) -> 800 | O8: N/A | P8: 2048 | R8: =IFERROR(N8+IF(ISNUMBER(O8),O8,0)+IF(ISNUMBER(P8),P8,0),"") -> 2848 | S8: Bondex
A9: Nhava Sheva-Manzanillo | B9: Creative Components | C9: Saltillo | D9: Nhava Sheva | E9: Manzanillo | F9: CIF | G9: 2 | H9: 70 | I9: 80 | J9: 160 | K9: 1000 | L9: 50 | M9: 75 | N9: =SUM(H9:M9) -> 1435 | O9: N/A | P9: 2500 | Q9: 50-55 days | R9: =IFERROR(N9+IF(ISNUMBER(O9),O9,0)+IF(ISNUMBER(P9),P9,0),"") -> 3935 | S9: KF
A10: Incheon-Manzanillo | B10: WOORY | C10: Saltillo | D10: Incheon | E10: Manzanillo | F10: CIF | G10: 1 | H10: 70 | I10: 35 | J10: 145 | K10: 350 | L10: 150 | M10: 50 | N10: =SUM(H10:M10) -> 800 | O10: N/A | P10: 2350 | Q10: 25-30 days | R10: =IFERROR(N10+IF(ISNUMBER(O10),O10,0)+IF(ISNUMBER(P10),P10,0),"") -> 3150 | S10: KF
A11: SHA-Manzanillo | B11: Jiangsu Chao Li | C11: Puebla | D11: SHA | E11: Manzanillo | F11: FOB | G11: 2 | H11: 70 | I11: 70 | J11: 145 | K11: 550 | L11: 15 | M11: 60 | N11: =SUM(H11:M11) -> 910 | O11: N/A | P11: 1749 | Q11: 18-23 days | R11: =IFERROR(N11+IF(ISNUMBER(O11),O11,0)+IF(ISNUMBER(P11),P11,0),"") -> 2659 | S11: Freetrans
A12: SHA-Manzanillo | B12: Yangzhou RSL | C12: Puebla | D12: SHA | E12: Manzanillo | F12: CIF | G12: 1 | H12: 70 | I12: 70 | J12: 145 | K12: 550 | L12: 15 | M12: 60 | N12: =SUM(H12:M12) -> 910 | O12: N/A | P12: 1749 | R12: =IFERROR(N12+IF(ISNUMBER(O12),O12,0)+IF(ISNUMBER(P12),P12,0),"") -> 2659 | S12: Freetrans
A13: SHA-Manzanillo | B13: Zhejiang Yuansheng | C13: Puebla | D13: SHA | E13: Manzanillo | F13: CIF | G13: 0.5 | H13: 70 | I13: 70 | J13: 145 | K13: 550 | L13: 15 | M13: 60 | N13: =SUM(H13:M13) -> 910 | O13: N/A | P13: 1749 | R13: =IFERROR(N13+IF(ISNUMBER(O13),O13,0)+IF(ISNUMBER(P13),P13,0),"") -> 2659 | S13: Freetrans
A14: SHA-Manzanillo | B14: Shanghai Huafon Coil | C14: Puebla | D14: SHA | E14: Manzanillo | F14: CIF | G14: 2 | H14: 70 | I14: 70 | J14: 145 | K14: 250 | L14: 15 | M14: 60 | N14: =SUM(H14:M14) -> 610 | O14: N/A | P14: 1749 | R14: =IFERROR(N14+IF(ISNUMBER(O14),O14,0)+IF(ISNUMBER(P14),P14,0),"") -> 2359 | S14: Freetrans
A15: SHA-Manzanillo | B15: Dalian ABIC | C15: Puebla | D15: SHA | E15: Manzanillo | F15: CIF | G15: 2 | H15: 70 | I15: 70 | J15: 145 | K15: 200 | L15: 15 | M15: 50 | N15: =SUM(H15:M15) -> 550 | O15: N/A | P15: 1749 | R15: =IFERROR(N15+IF(ISNUMBER(O15),O15,0)+IF(ISNUMBER(P15),P15,0),"") -> 2299 | S15: Freetrans
A16: SHA-Manzanillo | B16: Chongqing Boling | C16: Puebla | D16: SHA | E16: Manzanillo | F16: CIF | G16: 0.5 | H16: 70 | I16: 70 | J16: 145 | K16: 1550 | L16: 15 | M16: 60 | N16: =SUM(H16:M16) -> 1910 | O16: N/A | P16: 1749 | R16: =IFERROR(N16+IF(ISNUMBER(O16),O16,0)+IF(ISNUMBER(P16),P16,0),"") -> 3659 | S16: Freetrans
A17: SHA-Manzanillo | B17: AITD | C17: Saltillo | D17: SHA | E17: Manzanillo | F17: CIF | G17: 2 | H17: 70 | I17: 70 | J17: 145 | K17: 350 | L17: 15 | M17: 60 | N17: =SUM(H17:M17) -> 710 | O17: N/A | P17: 1749 | R17: =IFERROR(N17+IF(ISNUMBER(O17),O17,0)+IF(ISNUMBER(P17),P17,0),"") -> 2459 | S17: Freetrans
A18: SHA-Manzanillo | B18: Wuhu Bokang | C18: Saltillo | D18: SHA | E18: Manzanillo | F18: FOB | G18: 1 | H18: 70 | I18: 70 | J18: 145 | K18: 50 | L18: 15 | M18: 60 | N18: =SUM(H18:M18) -> 410 | O18: N/A | P18: 1749 | R18: =IFERROR(N18+IF(ISNUMBER(O18),O18,0)+IF(ISNUMBER(P18),P18,0),"") -> 2159 | S18: Freetrans
A19: SHA-Manzanillo | B19: Zhejiang Yida | C19: Puebla | D19: SHA | E19: Manzanillo | F19: CIF | G19: 1 | H19: 70 | I19: 70 | J19: 145 | K19: 550 | L19: 15 | M19: 60 | N19: =SUM(H19:M19) -> 910 | O19: N/A | P19: 1749 | R19: =IFERROR(N19+IF(ISNUMBER(O19),O19,0)+IF(ISNUMBER(P19),P19,0),"") -> 2659 | S19: Freetrans
A20: SHA-Manzanillo | B20: Nanjing PMC | C20: Saltillo | D20: SHA | E20: Manzanillo | F20: CIF | G20: 2 | H20: 70 | I20: 70 | J20: 145 | K20: 550 | L20: 15 | M20: 60 | N20: =SUM(H20:M20) -> 910 | O20: N/A | P20: 1749 | R20: =IFERROR(N20+IF(ISNUMBER(O20),O20,0)+IF(ISNUMBER(P20),P20,0),"") -> 2659 | S20: Freetrans
A21: SHA-Manzanillo | B21: Changsha Shenda | C21: Saltillo | D21: SHA | E21: Manzanillo | F21: CIF | G21: 2 | H21: 70 | I21: 70 | J21: 145 | K21: 1500 | L21: 15 | M21: 60 | N21: =SUM(H21:M21) -> 1860 | O21: N/A | P21: 1749 | R21: =IFERROR(N21+IF(ISNUMBER(O21),O21,0)+IF(ISNUMBER(P21),P21,0),"") -> 3609 | S21: Freetrans
A22: AIUS | USA (HOU / Detroit / Savanna) | 5 条航线 | 月需求 12 HQ40
